Workbook
Name Slicer_Department_Name: #N/A
Name Slicer_Emp_ID: #N/A
Name Slicer_Employment_satus: #N/A

Sheet Raw_Employee_Data
A1: Emp ID | B1: First_Name | C1: Last_Name | D1: Dept code | E1: Hire Date | F1: Salary | G1: Perf_Score | H1: Employment satus | I1: Full Name | J1: Department Name | K1: Years of Service | L1: Performance Band | M1: Eligible Bonus Amount
A2: EMP127 | B2: Emily | C2: Brown | D2: IT02 | E2: 43093 | F2: 50361 | G2: 52 | H2: Active | I2: =TRIM(B2&" "&C2) -> Emily Brown | J2: =VLOOKUP(D2,Lookup_Departments!$A$2:$B$7,2,FALSE) -> Information Technology | K2: =IF(H2="Active",DATEDIF(E2,TODAY(),"y"),"N/A") -> 8 | L2: =IF(G2="","No Score",VLOOKUP(G2,Lookup_Performance!$A$2:$D$6,3,TRUE)) -> Developing | M2: =IF(G2="",0,F2*VLOOKUP(G2,Lookup_Performance!$A$2:$D$6,4,TRUE)) -> 1007.22
A3: EMP046 | B3: Richard | C3: Hernandez | D3: MKT04 | E3: 43094 | F3: 112673 | H3: Active | I3: =TRIM(B3&" "&C3) -> Richard Hernandez | J3: =VLOOKUP(D3,Lookup_Departments!$A$2:$B$7,2,FALSE) -> Marketing | K3: =IF(H3="Active",DATEDIF(E3,TODAY(),"y"),"N/A") -> 8 | L3: =IF(G3="","No Score",VLOOKUP(G3,Lookup_Performance!$A$2:$D$6,3,TRUE)) -> No Score | M3: =IF(G3="",0,F3*VLOOKUP(G3,Lookup_Performance!$A$2:$D$6,4,TRUE)) -> 0
A4: EMP134 | B4: Emily | C4: Gonzalez | D4: IT02 | E4: 43095 | F4: 114425 | G4: 54 | H4: Left | I4: =TRIM(B4&" "&C4) -> Emily Gonzalez | J4: =VLOOKUP(D4,Lookup_Departments!$A$2:$B$7,2,FALSE) -> Information Technology | K4: =IF(H4="Active",DATEDIF(E4,TODAY(),"y"),"N/A") -> N/A | L4: =IF(G4="","No Score",VLOOKUP(G4,Lookup_Performance!$A$2:$D$6,3,TRUE)) -> Developing | M4: =IF(G4="",0,F4*VLOOKUP(G4,Lookup_Performance!$A$2:$D$6,4,TRUE)) -> 2288.5
A5: EMP139 | B5: John | C5: Martinez | D5: FIN03 | E5: 43096 | F5: 103831 | G5: 70 | H5: Active | I5: =TRIM(B5&" "&C5) -> John Martinez | J5: =VLOOKUP(D5,Lookup_Departments!$A$2:$B$7,2,FALSE) -> Finance | K5: =IF(H5="Active",DATEDIF(E5,TODAY(),"y"),"N/A") -> 8 | L5: =IF(G5="","No Score",VLOOKUP(G5,Lookup_Performance!$A$2:$D$6,3,TRUE)) -> Achieving | M5: =IF(G5="",0,F5*VLOOKUP(G5,Lookup_Performance!$A$2:$D$6,4,TRUE)) -> 5191.55
A6: EMP112 | B6: Thomas | C6: Smith | D6: IT02 | E6: 43097 | F6: 73785 | G6: 40 | H6: Left | I6: =TRIM(B6&" "&C6) -> Thomas Smith | J6: =VLOOKUP(D6,Lookup_Departments!$A$2:$B$7,2,FALSE) -> Information Technology | K6: =IF(H6="Active",DATEDIF(E6,TODAY(),"y"),"N/A") -> N/A | L6: =IF(G6="","No Score",VLOOKUP(G6,Lookup_Performance!$A$2:$D$6,3,TRUE)) -> Needs Improvement | M6: =IF(G6="",0,F6*VLOOKUP(G6,Lookup_Performance!$A$2:$D$6,4,TRUE)) -> 0
A7: EMP030 | B7: Emily | C7: Johnson | D7: OPS06 | E7: 43098 | F7: 115882 | G7: 49 | H7: Active | I7: =TRIM(B7&" "&C7) -> Emily Johnson | J7: =VLOOKUP(D7,Lookup_Departments!$A$2:$B$7,2,FALSE) -> Operations | K7: =IF(H7="Active",DATEDIF(E7,TODAY(),"y"),"N/A") -> 8 | L7: =IF(G7="","No Score",VLOOKUP(G7,Lookup_Performance!$A$2:$D$6,3,TRUE)) -> Needs Improvement | M7: =IF(G7="",0,F7*VLOOKUP(G7,Lookup_Performance!$A$2:$D$6,4,TRUE)) -> 0
A8: EMP096 | B8: John | C8: Wilson | D8: OPS06 | E8: 43099 | F8: 59980 | G8: 70 | H8: Left | I8: =TRIM(B8&" "&C8) -> John Wilson | J8: =VLOOKUP(D8,Lookup_Departments!$A$2:$B$7,2,FALSE) -> Operations | K8: =IF(H8="Active",DATEDIF(E8,TODAY(),"y"),"N/A") -> N/A | L8: =IF(G8="","No Score",VLOOKUP(G8,Lookup_Performance!$A$2:$D$6,3,TRUE)) -> Achieving | M8: =IF(G8="",0,F8*VLOOKUP(G8,Lookup_Performance!$A$2:$D$6,4,TRUE)) -> 2999
A9: EMP098 | B9: Jessica | C9: Smith | D9: OPS06 | E9: 43100 | F9: 68728 | G9: 45 | H9: Active | I9: =TRIM(B9&" "&C9) -> Jessica Smith | J9: =VLOOKUP(D9,Lookup_Departments!$A$2:$B$7,2,FALSE) -> Operations | K9: =IF(H9="Active",DATEDIF(E9,TODAY(),"y"),"N/A") -> 8 | L9: =IF(G9="","No Score",VLOOKUP(G9,Lookup_Performance!$A$2:$D$6,3,TRUE)) -> Needs Improvement | M9: =IF(G9="",0,F9*VLOOKUP(G9,Lookup_Performance!$A$2:$D$6,4,TRUE)) -> 0
A10: EMP095 | C10: Rodriguez | D10: FIN03 | E10: 43101 | F10: 102139 | G10: 79 | H10: Active | I10: =TRIM(B10&" "&C10) -> Rodriguez | J10: =VLOOKUP(D10,Lookup_Departments!$A$2:$B$7,2,FALSE) -> Finance | K10: =IF(H10="Active",DATEDIF(E10,TODAY(),"y"),"N/A") -> 8 | L10: =IF(G10="","No Score",VLOOKUP(G10,Lookup_Performance!$A$2:$D$6,3,TRUE)) -> Achieving | M10: =IF(G10="",0,F10*VLOOKUP(G10,Lookup_Performance!$A$2:$D$6,4,TRUE)) -> 5106.95
A11: EMP140 | B11: Michael | C11: Martinez | D11: SAL05 | E11: 43102 | F11: 94998 | G11: 58 | H11: Active | I11: =TRIM(B11&" "&C11) -> Michael Martinez | J11: =VLOOKUP(D11,Lookup_Departments!$A$2:$B$7,2,FALSE) -> Sales | K11: =IF(H11="Active",DATEDIF(E11,TODAY(),"y"),"N/A") -> 8 | L11: =IF(G11="","No Score",VLOOKUP(G11,Lookup_Performance!$A$2:$D$6,3,TRUE)) -> Developing | M11: =IF(G11="",0,F11*VLOOKUP(G11,Lookup_Performance!$A$2:$D$6,4,TRUE)) -> 1899.96
A12: EMP020 | B12: Emily | C12: Miller | D12: SAL05 | E12: 43103 | F12: 118635 | G12: 49 | H12: Active | I12: =TRIM(B12&" "&C12) -> Emily Miller | J12: =VLOOKUP(D12,Lookup_Departments!$A$2:$B$7,2,FALSE) -> Sales | K12: =IF(H12="Active",DATEDIF(E12,TODAY(),"y"),"N/A") -> 8 | L12: =IF(G12="","No Score",VLOOKUP(G12,Lookup_Performance!$A$2:$D$6,3,TRUE)) -> Needs Improvement | M12: =IF(G12="",0,F12*VLOOKUP(G12,Lookup_Performance!$A$2:$D$6,4,TRUE)) -> 0
A13: EMP057 | B13: Emily | C13: Hernandez | D13: IT02 | E13: 43104 | F13: 76918 | G13: 62 | H13: Active | I13: =TRIM(B13&" "&C13) -> Emily Hernandez | J13: =VLOOKUP(D13,Lookup_Departments!$A$2:$B$7,2,FALSE) -> Information Technology | K13: =IF(H13="Active",DATEDIF(E13,TODAY(),"y"),"N/A") -> 8 | L13: =IF(G13="","No Score",VLOOKUP(G13,Lookup_Performance!$A$2:$D$6,3,TRUE)) -> Developing | M13: =IF(G13="",0,F13*VLOOKUP(G13,Lookup_Performance!$A$2:$D$6,4,TRUE)) -> 1538.36
A14: EMP016 | B14: Jane | C14: Williams | D14: MKT04 | E14: 43105 | F14: 61408 | G14: 48 | H14: Active | I14: =TRIM(B14&" "&C14) -> Jane Williams | J14: =VLOOKUP(D14,Lookup_Departments!$A$2:$B$7,2,FALSE) -> Marketing | K14: =IF(H14="Active",DATEDIF(E14,TODAY(),"y"),"N/A") -> 8 | L14: =IF(G14="","No Score",VLOOKUP(G14,Lookup_Performance!$A$2:$D$6,3,TRUE)) -> Needs Improvement | M14: =IF(G14="",0,F14*VLOOKUP(G14,Lookup_Performance!$A$2:$D$6,4,TRUE)) -> 0
A15: EMP070 | B15: Jane | C15: Miller | D15: MKT04 | E15: 43106 | F15: 99990 | G15: 54 | H15: Active | I15: =TRIM(B15&" "&C15) -> Jane Miller | J15: =VLOOKUP(D15,Lookup_Departments!$A$2:$B$7,2,FALSE) -> Marketing | K15: =IF(H15="Active",DATEDIF(E15,TODAY(),"y"),"N/A") -> 8 | L15: =IF(G15="","No Score",VLOOKUP(G15,Lookup_Performance!$A$2:$D$6,3,TRUE)) -> Developing | M15: =IF(G15="",0,F15*VLOOKUP(G15,Lookup_Performance!$A$2:$D$6,4,TRUE)) -> 1999.8
A16: EMP025 | B16: Robert | C16: Jones | D16: MKT04 | E16: 43107 | F16: 80385 | H16: Active | I16: =TRIM(B16&" "&C16) -> Robert Jones | J16: =VLOOKUP(D16,Lookup_Departments!$A$2:$B$7,2,FALSE) -> Marketing | K16: =IF(H16="Active",DATEDIF(E16,TODAY(),"y"),"N/A") -> 8 | L16: =IF(G16="","No Score",VLOOKUP(G16,Lookup_Performance!$A$2:$D$6,3,TRUE)) -> No Score | M16: =IF(G16="",0,F16*VLOOKUP(G16,Lookup_Performance!$A$2:$D$6,4,TRUE)) -> 0
A17: EMP031 | B17: Thomas | C17: Rodriguez | D17: SAL05 | E17: 43108 | F17: 65290 | G17: 77 | H17: Active | I17: =TRIM(B17&" "&C17) -> Thomas Rodriguez | J17: =VLOOKUP(D17,Lookup_Departments!$A$2:$B$7,2,FALSE) -> Sales | K17: =IF(H17="Active",DATEDIF(E17,TODAY(),"y"),"N/A") -> 8 | L17: =IF(G17="","No Score",VLOOKUP(G17,Lookup_Performance!$A$2:$D$6,3,TRUE)) -> Achieving | M17: =IF(G17="",0,F17*VLOOKUP(G17,Lookup_Performance!$A$2:$D$6,4,TRUE)) -> 3264.5
A18: EMP126 | B18: Emily | C18: Davis | D18: IT02 | E18: 43109 | F18: 105765 | G18: 42 | H18: Active | I18: =TRIM(B18&" "&C18) -> Emily Davis | J18: =VLOOKUP(D18,Lookup_Departments!$A$2:$B$7,2,FALSE) -> Information Technology | K18: =IF(H18="Active",DATEDIF(E18,TODAY(),"y"),"N/A") -> 8 | L18: =IF(G18="","No Score",VLOOKUP(G18,Lookup_Performance!$A$2:$D$6,3,TRUE)) -> Needs Improvement | M18: =IF(G18="",0,F18*VLOOKUP(G18,Lookup_Performance!$A$2:$D$6,4,TRUE)) -> 0
A19: EMP109 | B19: James | C19: Martinez | D19: SAL05 | E19: 43110 | F19: 102921 | G19: 49 | H19: Active | I19: =TRIM(B19&" "&C19) -> James Martinez | J19: =VLOOKUP(D19,Lookup_Departments!$A$2:$B$7,2,FALSE) -> Sales | K19: =IF(H19="Active",DATEDIF(E19,TODAY(),"y"),"N/A") -> 8 | L19: =IF(G19="","No Score",VLOOKUP(G19,Lookup_Performance!$A$2:$D$6,3,TRUE)) -> Needs Improvement | M19: =IF(G19="",0,F19*VLOOKUP(G19,Lookup_Performance!$A$2:$D$6,4,TRUE)) -> 0
A20: EMP066 | B20: Ashley | C20: Lopez | D20: MKT04 | E20: 43111 | F20: 73984 | G20: 93 | H20: Active | I20: =TRIM(B20&" "&C20) -> Ashley Lopez | J20: =VLOOKUP(D20,Lookup_Departments!$A$2:$B$7,2,FALSE) -> Marketing | K20: =IF(H20="Active",DATEDIF(E20,TODAY(),"y"),"N/A") -> 8 | L20: =IF(G20="","No Score",VLOOKUP(G20,Lookup_Performance!$A$2:$D$6,3,TRUE)) -> Exceeding | M20: =IF(G20="",0,F20*VLOOKUP(G20,Lookup_Performance!$A$2:$D$6,4,TRUE)) -> 5918.72
A21: EMP120 | B21: Amanda | C21: Gonzalez | D21: IT02 | E21: 43112 | G21: 75 | H21: Active | I21: =TRIM(B21&" "&C21) -> Amanda Gonzalez | J21: =VLOOKUP(D21,Lookup_Departments!$A$2:$B$7,2,FALSE) -> Information Technology | K21: =IF(H21="Active",DATEDIF(E21,TODAY(),"y"),"N/A") -> 8 | L21: =IF(G21="","No Score",VLOOKUP(G21,Lookup_Performance!$A$2:$D$6,3,TRUE)) -> Achieving | M21: =IF(G21="",0,F21*VLOOKUP(G21,Lookup_Performance!$A$2:$D$6,4,TRUE)) -> 0
A22: EMP019 | B22: Michael | C22: Hernandez | D22: FIN03 | E22: 43113 | F22: 118527 | G22: 50 | H22: Active | I22: =TRIM(B22&" "&C22) -> Michael Hernandez | J22: =VLOOKUP(D22,Lookup_Departments!$A$2:$B$7,2,FALSE) -> Finance | K22: =IF(H22="Active",DATEDIF(E22,TODAY(),"y"),"N/A") -> 8 | L22: =IF(G22="","No Score",VLOOKUP(G22,Lookup_Performance!$A$2:$D$6,3,TRUE)) -> Developing | M22: =IF(G22="",0,F22*VLOOKUP(G22,Lookup_Performance!$A$2:$D$6,4,TRUE)) -> 2370.54
A23: EMP013 | B23: Richard | C23: Hernandez | D23: MKT04 | E23: 43114 | G23: 88 | H23: Active | I23: =TRIM(B23&" "&C23) -> Richard Hernandez | J23: =VLOOKUP(D23,Lookup_Departments!$A$2:$B$7,2,FALSE) -> Marketing | K23: =IF(H23="Active",DATEDIF(E23,TODAY(),"y"),"N/A") -> 8 | L23: =IF(G23="","No Score",VLOOKUP(G23,Lookup_Performance!$A$2:$D$6,3,TRUE)) -> Exceeding | M23: =IF(G23="",0,F23*VLOOKUP(G23,Lookup_Performance!$A$2:$D$6,4,TRUE)) -> 0
A24: EMP010 | B24: Michael | C24: Rodriguez | D24: IT02 | E24: 43115 | F24: 93956 | G24: 50 | H24: Left | I24: =TRIM(B24&" "&C24) -> Michael Rodriguez | J24: =VLOOKUP(D24,Lookup_Departments!$A$2:$B$7,2,FALSE) -> Information Technology | K24: =IF(H24="Active",DATEDIF(E24,TODAY(),"y"),"N/A") -> N/A | L24: =IF(G24="","No Score",VLOOKUP(G24,Lookup_Performance!$A$2:$D$6,3,TRUE)) -> Developing | M24: =IF(G24="",0,F24*VLOOKUP(G24,Lookup_Performance!$A$2:$D$6,4,TRUE)) -> 1879.12
A25: EMP032 | B25: Jessica | C25: Johnson | D25: FIN03 | E25: 43116 | F25: 100851 | G25: 64 | H25: Active | I25: =TRIM(B25&" "&C25) -> Jessica Johnson | J25: =VLOOKUP(D25,Lookup_Departments!$A$2:$B$7,2,FALSE) -> Finance | K25: =IF(H25="Active",DATEDIF(E25,TODAY(),"y"),"N/A") -> 8 | L25: =IF(G25="","No Score",VLOOKUP(G25,Lookup_Performance!$A$2:$D$6,3,TRUE)) -> Developing | M25: =IF(G25="",0,F25*VLOOKUP(G25,Lookup_Performance!$A$2:$D$6,4,TRUE)) -> 2017.02
A26: EMP082 | B26: Ashley | C26: Williams | D26: SAL05 | E26: 43117 | F26: 68655 | G26: 32 | H26: Active | I26: =TRIM(B26&" "&C26) -> Ashley Williams | J26: =VLOOKUP(D26,Lookup_Departments!$A$2:$B$7,2,FALSE) -> Sales | K26: =IF(H26="Active",DATEDIF(E26,TODAY(),"y"),"N/A") -> 8 | L26: =IF(G26="","No Score",VLOOKUP(G26,Lookup_Performance!$A$2:$D$6,3,TRUE)) -> Needs Improvement | M26: =IF(G26="",0,F26*VLOOKUP(G26,Lookup_Performance!$A$2:$D$6,4,TRUE)) -> 0
A27: EMP052 | C27: Williams | D27: SAL05 | E27: 43118 | F27: 81205 | G27: 59 | H27: Active | I27: =TRIM(B27&" "&C27) -> Williams | J27: =VLOOKUP(D27,Lookup_Departments!$A$2:$B$7,2,FALSE) -> Sales | K27: =IF(H27="Active",DATEDIF(E27,TODAY(),"y"),"N/A") -> 8 | L27: =IF(G27="","No Score",VLOOKUP(G27,Lookup_Performance!$A$2:$D$6,3,TRUE)) -> Developing | M27: =IF(G27="",0,F27*VLOOKUP(G27,Lookup_Performance!$A$2:$D$6,4,TRUE)) -> 1624.1
A28: EMP129 | B28: John | C28: Wilson | D28: SAL05 | E28: 43119 | F28: 77610 | G28: 88 | H28: Active | I28: =TRIM(B28&" "&C28) -> John Wilson | J28: =VLOOKUP(D28,Lookup_Departments!$A$2:$B$7,2,FALSE) -> Sales | K28: =IF(H28="Active",DATEDIF(E28,TODAY(),"y"),"N/A") -> 8 | L28: =IF(G28="","No Score",VLOOKUP(G28,Lookup_Performance!$A$2:$D$6,3,TRUE)) -> Exceeding | M28: =IF(G28="",0,F28*VLOOKUP(G28,Lookup_Performance!$A$2:$D$6,4,TRUE)) -> 6208.8
A29: EMP146 | B29: Thomas | C29: Rodriguez | D29: IT02 | E29: 43120 | F29: 50873 | G29: 90 | H29: Active | I29: =TRIM(B29&" "&C29) -> Thomas Rodriguez | J29: =VLOOKUP(D29,Lookup_Departments!$A$2:$B$7,2,FALSE) -> Information Technology | K29: =IF(H29="Active",DATEDIF(E29,TODAY(),"y"),"N/A") -> 8 | L29: =IF(G29="","No Score",VLOOKUP(G29,Lookup_Performance!$A$2:$D$6,3,TRUE)) -> Exceeding | M29: =IF(G29="",0,F29*VLOOKUP(G29,Lookup_Performance!$A$2:$D$6,4,TRUE)) -> 4069.84
A30: EMP099 | B30: Michael | C30: Wilson | D30: FIN03 | E30: 43121 | F30: 85312 | G30: 66 | H30: Active | I30: =TRIM(B30&" "&C30) -> Michael Wilson | J30: =VLOOKUP(D30,Lookup_Departments!$A$2:$B$7,2,FALSE) -> Finance | K30: =IF(H30="Active",DATEDIF(E30,TODAY(),"y"),"N/A") -> 8 | L30: =IF(G30="","No Score",VLOOKUP(G30,Lookup_Performance!$A$2:$D$6,3,TRUE)) -> Developing | M30: =IF(G30="",0,F30*VLOOKUP(G30,Lookup_Performance!$A$2:$D$6,4,TRUE)) -> 1706.24
A31: EMP015 | B31: John | C31: Rodriguez | D31: SAL05 | E31: 43122 | G31: 68 | H31: Active | I31: =TRIM(B31&" "&C31) -> John Rodriguez | J31: =VLOOKUP(D31,Lookup_Departments!$A$2:$B$7,2,FALSE) -> Sales | K31: =IF(H31="Active",DATEDIF(E31,TODAY(),"y"),"N/A") -> 8 | L31: =IF(G31="","No Score",VLOOKUP(G31,Lookup_Performance!$A$2:$D$6,3,TRUE)) -> Developing | M31: =IF(G31="",0,F31*VLOOKUP(G31,Lookup_Performance!$A$2:$D$6,4,TRUE)) -> 0
A32: EMP076 | B32: Thomas | C32: Hernandez | D32: OPS06 | E32: 43123 | F32: 97055 | G32: 80 | H32: Active | I32: =TRIM(B32&" "&C32) -> Thomas Hernandez | J32: =VLOOKUP(D32,Lookup_Departments!$A$2:$B$7,2,FALSE) -> Operations | K32: =IF(H32="Active",DATEDIF(E32,TODAY(),"y"),"N/A") -> 8 | L32: =IF(G32="","No Score",VLOOKUP(G32,Lookup_Performance!$A$2:$D$6,3,TRUE)) -> Achieving | M32: =IF(G32="",0,F32*VLOOKUP(G32,Lookup_Performance!$A$2:$D$6,4,TRUE)) -> 4852.75
A33: EMP137 | B33: Michael | C33: Johnson | D33: IT02 | E33: 43124 | F33: 66069 | G33: 72 | H33: Active | I33: =TRIM(B33&" "&C33) -> Michael Johnson | J33: =VLOOKUP(D33,Lookup_Departments!$A$2:$B$7,2,FALSE) -> Information Technology | K33: =IF(H33="Active",DATEDIF(E33,TODAY(),"y"),"N/A") -> 8 | L33: =IF(G33="","No Score",VLOOKUP(G33,Lookup_Performance!$A$2:$D$6,3,TRUE)) -> Achieving | M33: =IF(G33="",0,F33*VLOOKUP(G33,Lookup_Performance!$A$2:$D$6,4,TRUE)) -> 3303.45
A34: EMP056 | B34: Sarah | C34: Brown | D34: IT02 | E34: 43125 | F34: 90157 | G34: 58 | H34: Active | I34: =TRIM(B34&" "&C34) -> Sarah Brown | J34: =VLOOKUP(D34,Lookup_Departments!$A$2:$B$7,2,FALSE) -> Information Technology | K34: =IF(H34="Active",DATEDIF(E34,TODAY(),"y"),"N/A") -> 8 | L34: =IF(G34="","No Score",VLOOKUP(G34,Lookup_Performance!$A$2:$D$6,3,TRUE)) -> Developing | M34: =IF(G34="",0,F34*VLOOKUP(G34,Lookup_Performance!$A$2:$D$6,4,TRUE)) -> 1803.14
A35: EMP125 | B35: Jane | C35: Martinez | D35: HR01 | E35: 43126 | F35: 59899 | G35: 78 | H35: Active | I35: =TRIM(B35&" "&C35) -> Jane Martinez | J35: =VLOOKUP(D35,Lookup_Departments!$A$2:$B$7,2,FALSE) -> Human Resources | K35: =IF(H35="Active",DATEDIF(E35,TODAY(),"y"),"N/A") -> 8 | L35: =IF(G35="","No Score",VLOOKUP(G35,Lookup_Performance!$A$2:$D$6,3,TRUE)) -> Achieving | M35: =IF(G35="",0,F35*VLOOKUP(G35,Lookup_Performance!$A$2:$D$6,4,TRUE)) -> 2994.95
A36: EMP085 | B36: Emily | C36: Jones | D36: FIN03 | E36: 43127 | F36: 113389 | G36: 30 | H36: Active | I36: =TRIM(B36&" "&C36) -> Emily Jones | J36: =VLOOKUP(D36,Lookup_Departments!$A$2:$B$7,2,FALSE) -> Finance | K36: =IF(H36="Active",DATEDIF(E36,TODAY(),"y"),"N/A") -> 8 | L36: =IF(G36="","No Score",VLOOKUP(G36,Lookup_Performance!$A$2:$D$6,3,TRUE)) -> Needs Improvement | M36: =IF(G36="",0,F36*VLOOKUP(G36,Lookup_Performance!$A$2:$D$6,4,TRUE)) -> 0
A37: EMP106 | C37: Brown | D37: IT02 | E37: 43128 | F37: 102691 | G37: 52 | H37: Active | I37: =TRIM(B37&" "&C37) -> Brown | J37: =VLOOKUP(D37,Lookup_Departments!$A$2:$B$7,2,FALSE) -> Information Technology | K37: =IF(H37="Active",DATEDIF(E37,TODAY(),"y"),"N/A") -> 8 | L37: =IF(G37="","No Score",VLOOKUP(G37,Lookup_Performance!$A$2:$D$6,3,TRUE)) -> Developing | M37: =IF(G37="",0,F37*VLOOKUP(G37,Lookup_Performance!$A$2:$D$6,4,TRUE)) -> 2053.82
A38: EMP043 | B38: John | C38: Wilson | D38: OPS06 | E38: 43129 | F38: 111845 | G38: 98 | H38: Active | I38: =TRIM(B38&" "&C38) -> John Wilson | J38: =VLOOKUP(D38,Lookup_Departments!$A$2:$B$7,2,FALSE) -> Operations | K38: =IF(H38="Active",DATEDIF(E38,TODAY(),"y"),"N/A") -> 8 | L38: =IF(G38="","No Score",VLOOKUP(G38,Lookup_Performance!$A$2:$D$6,3,TRUE)) -> Outstanding | M38: =IF(G38="",0,F38*VLOOKUP(G38,Lookup_Performance!$A$2:$D$6,4,TRUE)) -> 13421.4
A39: EMP068 | B39: Melissa | C39: Brown | D39: SAL05 | E39: 43130 | F39: 69219 | G39: 93 | H39: Active | I39: =TRIM(B39&" "&C39) -> Melissa Brown | J39: =VLOOKUP(D39,Lookup_Departments!$A$2:$B$7,2,FALSE) -> Sales | K39: =IF(H39="Active",DATEDIF(E39,TODAY(),"y"),"N/A") -> 8 | L39: =IF(G39="","No Score",VLOOKUP(G39,Lookup_Performance!$A$2:$D$6,3,TRUE)) -> Exceeding | M39: =IF(G39="",0,F39*VLOOKUP(G39,Lookup_Performance!$A$2:$D$6,4,TRUE)) -> 5537.52
A40: EMP128 | B40: Michael | C40: Smith | D40: FIN03 | E40: 43131 | G40: 80 | H40: Left | I40: =TRIM(B40&" "&C40) -> Michael Smith | J40: =VLOOKUP(D40,Lookup_Departments!$A$2:$B$7,2,FALSE) -> Finance | K40: =IF(H40="Active",DATEDIF(E40,TODAY(),"y"),"N/A") -> N/A | L40: =IF(G40="","No Score",VLOOKUP(G40,Lookup_Performance!$A$2:$D$6,3,TRUE)) -> Achieving | M40: =IF(G40="",0,F40*VLOOKUP(G40,Lookup_Performance!$A$2:$D$6,4,TRUE)) -> 0
...

Sheet Lookup_Departments
A1: Dept_Code | B1: Department_Name
A2: HR01 | B2: Human Resources
A3: IT02 | B3: Information Technology
A4: FIN03 | B4: Finance
A5: MKT04 | B5: Marketing
A6: SAL05 | B6: Sales
A7: OPS06 | B7: Operations

Sheet Lookup_Performance
A1: Min_Score | B1: Max_Score | C1: Performance_Band | D1: Bonus_Percentage
A2: 0 | B2: 49 | C2: Needs Improvement | D2: 0
A3: 50 | B3: 69 | C3: Developing | D3: 0.02
A4: 70 | B4: 84 | C4: Achieving | D4: 0.05
A5: 85 | B5: 94 | C5: Exceeding | D5: 0.08
A6: 95 | B6: 100 | C6: Outstanding | D6: 0.12

Sheet Analysis
B2: Headcount & Salary | F2: Attrition Rate | O2: Bonus Payout
A3: Department | B3: Count of Emp ID | C3: Average Salary | E3: Department | O3: Performance Band | P3: Sum of Eligible Bonus Amount
A4: Finance | B4: 17 | C4: 87938.5 | F4: Active | G4: Left | H4: Resigned | O4: Achieving | P4: 144315.95
A5: Human Resources | B5: 18 | C5: 85649.941 | E5: Finance | F5: 0.12068966 | G5: 0.125 | H5: 0 | O5: Exceeding | P5: 122683.12
A6: Information Technology | B6: 36 | C6: 80014.258 | E6: Human Resources | F6: 0.12931034 | G6: 0.083333333 | H6: 0.1 | O6: Outstanding | P6: 82379.04
A7: Marketing | B7: 19 | C7: 84192.706 | E7: Information Technology | F7: 0.24137931 | G7: 0.25 | H7: 0.2 | O7: Developing | P7: 58138.3
A8: Operations | B8: 29 | C8: 79786.667 | E8: Marketing | F8: 0.13793103 | G8: 0.125 | H8: 0 | O8: No Score | P8: 0
A9: Sales | B9: 31 | C9: 87282.348 | E9: Operations | F9: 0.15517241 | G9: 0.25 | H9: 0.5 | O9: Needs Improvement | P9: 0
E10: Sales | F10: 0.21551724 | G10: 0.16666667 | H10: 0.2
A14: Performance By Status | E14: Bonus Payout
A15: Employee Status | B15: Average of Perf_Score | E15: Performance Band | F15: Sum of Eligible Bonus Amount
A16: Active | B16: 67.724771 | E16: Achieving | F16: 144315.95
A17: Left | B17: 66.130435 | E17: Exceeding | F17: 122683.12
A18: Resigned | B18: 76.4 | E18: Outstanding | F18: 82379.04
E19: Developing | F19: 58138.3
E20: No Score | F20: 0
E21: Needs Improvement | F21: 0

Sheet KPIs
A2: Total Employee | C2: Average Salary | E2: Row Labels | F2: No of Employees | G2: Attrition rate
A3: 150 | C3: 83415.814 | E3: Active | F3: 116 | G3: 0.77333333
E4: Left | F4: 24 | G4: 0.16
E5: Resigned | F5: 10 | G5: 0.066666667

Sheet HR Dashboard
